Workbook
Name Slicer_Months__Date: #N/A

Sheet Processing
A1: Total Revenue | B1: Total Spend | C1: Total Impressions | D1: Total Conversions | E1: Cost Per Conversion | F1: Total ROI
A2: =GETPIVOTDATA("Sum of Revenue",Pivot!$B$3) -> 33577968 | B2: =GETPIVOTDATA("Sum of Spend",Pivot!$B$3) -> 4113972.8 | C2: =GETPIVOTDATA("Sum of Impressions",Pivot!$B$3) -> 96928090 | D2: =GETPIVOTDATA("Sum of Conversions",Pivot!$B$3) -> 207860 | E2: =B2/D2 -> 19.792037 | F2: =ROUND((A2-B2)/B2,1)&"%" -> 7.2%
A3: YOY Growth % | B3: YOY Growth % | C3: YOY Growth % | D3: YOY Growth % | E3: YOY Growth % | F3: YOY Growth %
A4: =(GETPIVOTDATA("Sum of Revenue",Pivot!$B$3,"Years (Date)",2024)-GETPIVOTDATA("Sum of Revenue",Pivot!$B$3,"Years (Date)",2023))/GETPIVOTDATA("Sum of Revenue",Pivot!$B$3,"Years (Date)",2023) -> 0.49381285 | B4: =(GETPIVOTDATA("Sum of Spend",Pivot!$B$3,"Years (Date)",2024)-GETPIVOTDATA("Sum of Spend",Pivot!$B$3,"Years (Date)",2023))/GETPIVOTDATA("Sum of Spend",Pivot!$B$3,"Years (Date)",2023) -> 0.50141543 | C4: =(GETPIVOTDATA("Sum of Impressions",Pivot!$B$3,"Years (Date)",2024)-GETPIVOTDATA("Sum of Impressions",Pivot!$B$3,"Years (Date)",2023))/GETPIVOTDATA("Sum of Impressions",Pivot!$B$3,"Years (Date)",2023) -> 0.47123547 | D4: =(GETPIVOTDATA("Sum of Conversions",Pivot!$B$3,"Years (Date)",2024)-GETPIVOTDATA("Sum of Conversions",Pivot!$B$3,"Years (Date)",2023))/GETPIVOTDATA("Sum of Conversions",Pivot!$B$3,"Years (Date)",2023) -> 0.48811961 | E4: =(GETPIVOTDATA("Average of CPC",Pivot!$B$3,"Years (Date)",2024)-GETPIVOTDATA("Average of CPC",Pivot!$B$3,"Years (Date)",2023))/GETPIVOTDATA("Average of CPC",Pivot!$B$3,"Years (Date)",2023) -> 0.25557959
A5: =IF(A4>0,A4,"") -> 0.49381285 | B5: =IF(B4>0,B4,"") -> 0.50141543 | C5: =IF(C4>0,C4,"") -> 0.47123547 | D5: =IF(D4>0,D4,"") -> 0.48811961 | E5: =IF(E4>0,E4,"") -> 0.25557959 | F5: Positive
A6: =IF(A4<=0,A4,"") | B6: =IF(B4<=0,B4,"") | C6: =IF(C4<=0,C4,"") | D6: =IF(D4<=0,D4,"") | E6: =IF(E4<=0,E4,"") | F6: Negative
D9: TRUE | E9: =MAX(B11:B22)*5% -> 114392.76
A10: Monthly Revenue Trend | B10: Revenue | C10: Cursor R | D10: Previous | E10: Label | F10: TRUE | G10: 2024 | H10: 2023
A11: Jan | B11: =GETPIVOTDATA("Revenue",Pivot!$B$28,"Months (Date)",A11,"Years (Date)",2024) -> 1201288.6 | C11: =IF($F$10,IFERROR(GETPIVOTDATA("Revenue",Pivot!$B$10,"Months (Date)",A11,"Years (Date)",2024),NA()),NA()) -> 1201288.6 | D11: =IF($D$9,GETPIVOTDATA("Revenue",Pivot!$B$28,"Months (Date)",A11,"Years (Date)",2023),NA()) -> 589125 | E11: =IF($F$10,C11+$E$9,NA()) -> 1315681.4 | G11: =IFERROR(GETPIVOTDATA("Revenue",Pivot!$B$10,"Months (Date)",A11,"Years (Date)",2024),NA()) -> 1201288.6 | H11: =IFERROR(GETPIVOTDATA("Revenue",Pivot!$B$28,"Months (Date)",A11,"Years (Date)",2023),NA()) -> 589125
A12: Feb | B12: =GETPIVOTDATA("Revenue",Pivot!$B$28,"Months (Date)",A12,"Years (Date)",2024) -> 1270928 | C12: =IF($F$10,IFERROR(GETPIVOTDATA("Revenue",Pivot!$B$10,"Months (Date)",A12,"Years (Date)",2024),NA()),NA()) -> 1270928 | D12: =IF($D$9,GETPIVOTDATA("Revenue",Pivot!$B$28,"Months (Date)",A12,"Years (Date)",2023),NA()) -> 720000 | E12: =IF($F$10,C12+$E$9,NA()) -> 1385320.8 | G12: =IFERROR(GETPIVOTDATA("Revenue",Pivot!$B$10,"Months (Date)",A12,"Years (Date)",2024),NA()) -> 1270928 | H12: =IFERROR(GETPIVOTDATA("Revenue",Pivot!$B$28,"Months (Date)",A12,"Years (Date)",2023),NA()) -> 720000
A13: Mar | B13: =GETPIVOTDATA("Revenue",Pivot!$B$28,"Months (Date)",A13,"Years (Date)",2024) -> 1234813.9 | C13: =IF($F$10,IFERROR(GETPIVOTDATA("Revenue",Pivot!$B$10,"Months (Date)",A13,"Years (Date)",2024),NA()),NA()) -> 1234813.9 | D13: =IF($D$9,GETPIVOTDATA("Revenue",Pivot!$B$28,"Months (Date)",A13,"Years (Date)",2023),NA()) -> 779250 | E13: =IF($F$10,C13+$E$9,NA()) -> 1349206.6 | G13: =IFERROR(GETPIVOTDATA("Revenue",Pivot!$B$10,"Months (Date)",A13,"Years (Date)",2024),NA()) -> 1234813.9 | H13: =IFERROR(GETPIVOTDATA("Revenue",Pivot!$B$28,"Months (Date)",A13,"Years (Date)",2023),NA()) -> 779250
A14: Apr | B14: =GETPIVOTDATA("Revenue",Pivot!$B$28,"Months (Date)",A14,"Years (Date)",2024) -> 1270451.2 | C14: =IF($F$10,IFERROR(GETPIVOTDATA("Revenue",Pivot!$B$10,"Months (Date)",A14,"Years (Date)",2024),NA()),NA()) -> 1270451.2 | D14: =IF($D$9,GETPIVOTDATA("Revenue",Pivot!$B$28,"Months (Date)",A14,"Years (Date)",2023),NA()) -> 902383.31 | E14: =IF($F$10,C14+$E$9,NA()) -> 1384844 | G14: =IFERROR(GETPIVOTDATA("Revenue",Pivot!$B$10,"Months (Date)",A14,"Years (Date)",2024),NA()) -> 1270451.2 | H14: =IFERROR(GETPIVOTDATA("Revenue",Pivot!$B$28,"Months (Date)",A14,"Years (Date)",2023),NA()) -> 902383.31
A15: May | B15: =GETPIVOTDATA("Revenue",Pivot!$B$28,"Months (Date)",A15,"Years (Date)",2024) -> 1590982.5 | C15: =IF($F$10,IFERROR(GETPIVOTDATA("Revenue",Pivot!$B$10,"Months (Date)",A15,"Years (Date)",2024),NA()),NA()) -> 1590982.5 | D15: =IF($D$9,GETPIVOTDATA("Revenue",Pivot!$B$28,"Months (Date)",A15,"Years (Date)",2023),NA()) -> 1070748.3 | E15: =IF($F$10,C15+$E$9,NA()) -> 1705375.3 | G15: =IFERROR(GETPIVOTDATA("Revenue",Pivot!$B$10,"Months (Date)",A15,"Years (Date)",2024),NA()) -> 1590982.5 | H15: =IFERROR(GETPIVOTDATA("Revenue",Pivot!$B$28,"Months (Date)",A15,"Years (Date)",2023),NA()) -> 1070748.3
A16: Jun | B16: =GETPIVOTDATA("Revenue",Pivot!$B$28,"Months (Date)",A16,"Years (Date)",2024) -> 1443615.8 | C16: =IF($F$10,IFERROR(GETPIVOTDATA("Revenue",Pivot!$B$10,"Months (Date)",A16,"Years (Date)",2024),NA()),NA()) -> 1443615.8 | D16: =IF($D$9,GETPIVOTDATA("Revenue",Pivot!$B$28,"Months (Date)",A16,"Years (Date)",2023),NA()) -> 965588.26 | E16: =IF($F$10,C16+$E$9,NA()) -> 1558008.6 | G16: =IFERROR(GETPIVOTDATA("Revenue",Pivot!$B$10,"Months (Date)",A16,"Years (Date)",2024),NA()) -> 1443615.8 | H16: =IFERROR(GETPIVOTDATA("Revenue",Pivot!$B$28,"Months (Date)",A16,"Years (Date)",2023),NA()) -> 965588.26
A17: Jul | B17: =GETPIVOTDATA("Revenue",Pivot!$B$28,"Months (Date)",A17,"Years (Date)",2024) -> 1714874.9 | C17: =IF($F$10,IFERROR(GETPIVOTDATA("Revenue",Pivot!$B$10,"Months (Date)",A17,"Years (Date)",2024),NA()),NA()) -> 1714874.9 | D17: =IF($D$9,GETPIVOTDATA("Revenue",Pivot!$B$28,"Months (Date)",A17,"Years (Date)",2023),NA()) -> 1290750 | E17: =IF($F$10,C17+$E$9,NA()) -> 1829267.7 | G17: =IFERROR(GETPIVOTDATA("Revenue",Pivot!$B$10,"Months (Date)",A17,"Years (Date)",2024),NA()) -> 1714874.9 | H17: =IFERROR(GETPIVOTDATA("Revenue",Pivot!$B$28,"Months (Date)",A17,"Years (Date)",2023),NA()) -> 1290750
A18: Aug | B18: =GETPIVOTDATA("Revenue",Pivot!$B$28,"Months (Date)",A18,"Years (Date)",2024) -> 1861950.7 | C18: =IF($F$10,IFERROR(GETPIVOTDATA("Revenue",Pivot!$B$10,"Months (Date)",A18,"Years (Date)",2024),NA()),NA()) -> 1861950.7 | D18: =IF($D$9,GETPIVOTDATA("Revenue",Pivot!$B$28,"Months (Date)",A18,"Years (Date)",2023),NA()) -> 1308973.2 | E18: =IF($F$10,C18+$E$9,NA()) -> 1976343.4 | G18: =IFERROR(GETPIVOTDATA("Revenue",Pivot!$B$10,"Months (Date)",A18,"Years (Date)",2024),NA()) -> 1861950.7 | H18: =IFERROR(GETPIVOTDATA("Revenue",Pivot!$B$28,"Months (Date)",A18,"Years (Date)",2023),NA()) -> 1308973.2
A19: Sep | B19: =GETPIVOTDATA("Revenue",Pivot!$B$28,"Months (Date)",A19,"Years (Date)",2024) -> 2287855.2 | C19: =IF($F$10,IFERROR(GETPIVOTDATA("Revenue",Pivot!$B$10,"Months (Date)",A19,"Years (Date)",2024),NA()),NA()) -> 2287855.2 | D19: =IF($D$9,GETPIVOTDATA("Revenue",Pivot!$B$28,"Months (Date)",A19,"Years (Date)",2023),NA()) -> 1233473 | E19: =IF($F$10,C19+$E$9,NA()) -> 2402247.9 | G19: =IFERROR(GETPIVOTDATA("Revenue",Pivot!$B$10,"Months (Date)",A19,"Years (Date)",2024),NA()) -> 2287855.2 | H19: =IFERROR(GETPIVOTDATA("Revenue",Pivot!$B$28,"Months (Date)",A19,"Years (Date)",2023),NA()) -> 1233473
A20: Oct | B20: =GETPIVOTDATA("Revenue",Pivot!$B$28,"Months (Date)",A20,"Years (Date)",2024) -> 2190555.2 | C20: =IF($F$10,IFERROR(GETPIVOTDATA("Revenue",Pivot!$B$10,"Months (Date)",A20,"Years (Date)",2024),NA()),NA()) -> 2190555.2 | D20: =IF($D$9,GETPIVOTDATA("Revenue",Pivot!$B$28,"Months (Date)",A20,"Years (Date)",2023),NA()) -> 1343468 | E20: =IF($F$10,C20+$E$9,NA()) -> 2304948 | G20: =IFERROR(GETPIVOTDATA("Revenue",Pivot!$B$10,"Months (Date)",A20,"Years (Date)",2024),NA()) -> 2190555.2 | H20: =IFERROR(GETPIVOTDATA("Revenue",Pivot!$B$28,"Months (Date)",A20,"Years (Date)",2023),NA()) -> 1343468
A21: Nov | B21: =GETPIVOTDATA("Revenue",Pivot!$B$28,"Months (Date)",A21,"Years (Date)",2024) -> 2094258.2 | C21: =IF($F$10,IFERROR(GETPIVOTDATA("Revenue",Pivot!$B$10,"Months (Date)",A21,"Years (Date)",2024),NA()),NA()) -> 2094258.2 | D21: =IF($D$9,GETPIVOTDATA("Revenue",Pivot!$B$28,"Months (Date)",A21,"Years (Date)",2023),NA()) -> 1428955.4 | E21: =IF($F$10,C21+$E$9,NA()) -> 2208651 | G21: =IFERROR(GETPIVOTDATA("Revenue",Pivot!$B$10,"Months (Date)",A21,"Years (Date)",2024),NA()) -> 2094258.2 | H21: =IFERROR(GETPIVOTDATA("Revenue",Pivot!$B$28,"Months (Date)",A21,"Years (Date)",2023),NA()) -> 1428955.4
A22: Dec | B22: =GETPIVOTDATA("Revenue",Pivot!$B$28,"Months (Date)",A22,"Years (Date)",2024) -> 1951883.8 | C22: =IF($F$10,IFERROR(GETPIVOTDATA("Revenue",Pivot!$B$10,"Months (Date)",A22,"Years (Date)",2024),NA()),NA()) -> 1951883.8 | D22: =IF($D$9,GETPIVOTDATA("Revenue",Pivot!$B$28,"Months (Date)",A22,"Years (Date)",2023),NA()) -> 1831795.7 | E22: =IF($F$10,C22+$E$9,NA()) -> 2066276.6 | G22: =IFERROR(GETPIVOTDATA("Revenue",Pivot!$B$10,"Months (Date)",A22,"Years (Date)",2024),NA()) -> 1951883.8 | H22: =IFERROR(GETPIVOTDATA("Revenue",Pivot!$B$28,"Months (Date)",A22,"Years (Date)",2023),NA()) -> 1831795.7
C23: =SUMIF(G11:G22,">0") -> 20113458 | D23: =SUMIF(G11:G22,">0",H11:H22) -> 13464510
A27: Revenue & Conversions by Channel | D27: =MAX(B28:B31)*5% -> 710062.65
A28: Direct Mail | B28: =GETPIVOTDATA("Sum of Revenue",Pivot!$B$46,"Marketing_Channel",A28) -> 4917146.7 | C28: =GETPIVOTDATA("Sum of Conversions",Pivot!$B$46,"Marketing_Channel",A28) -> 19518 | D28: =$D$27 -> 710062.65
A29: Social Media | B29: =GETPIVOTDATA("Sum of Revenue",Pivot!$B$46,"Marketing_Channel",A29) -> 6936289.6 | C29: =GETPIVOTDATA("Sum of Conversions",Pivot!$B$46,"Marketing_Channel",A29) -> 44732 | D29: =$D$27 -> 710062.65
A30: Search Engine | B30: =GETPIVOTDATA("Sum of Revenue",Pivot!$B$46,"Marketing_Channel",A30) -> 7523279 | C30: =GETPIVOTDATA("Sum of Conversions",Pivot!$B$46,"Marketing_Channel",A30) -> 49608 | D30: =$D$27 -> 710062.65
A31: Email | B31: =GETPIVOTDATA("Sum of Revenue",Pivot!$B$46,"Marketing_Channel",A31) -> 14201253 | C31: =GETPIVOTDATA("Sum of Conversions",Pivot!$B$46,"Marketing_Channel",A31) -> 94002 | D31: =$D$27 -> 710062.65
A35: Revenue by Region | B35: P1 | C35: P2 | D35: P3
A36: South | B36: =GETPIVOTDATA("Revenue",Pivot!$B$89,"Region",A36) -> 11746551 | C36: =B36 -> 11746551 | D36: =C36 -> 11746551
A37: North | B37: =GETPIVOTDATA("Revenue",Pivot!$B$89,"Region",A37) -> 9635644.3 | C37: =B37 -> 9635644.3 | D37: =C37 -> 9635644.3
A38: West | B38: =GETPIVOTDATA("Revenue",Pivot!$B$89,"Region",A38) -> 7172633.1 | C38: =B38 -> 7172633.1 | D38: =C38 -> 7172633.1
A39: East | B39: =GETPIVOTDATA("Revenue",Pivot!$B$89,"Region",A39) -> 5023139.8 | C39: =B39 -> 5023139.8 | D39: =C39 -> 5023139.8
A43: Revenue by Category | B43: Revenue
A44: Electronics | B44: =GETPIVOTDATA("Revenue",Pivot!$B$98,"Category",A44) -> 15082727
A45: Fashion | B45: =GETPIVOTDATA("Revenue",Pivot!$B$98,"Category",A45) -> 12172957
A46: Health & Fitness | B46: =GETPIVOTDATA("Revenue",Pivot!$B$98,"Category",A46) -> 6322284.3
B48: Spent | C48: Revenue | D48: ROI
A49: {=_xlfn._xlws.SORT(Pivot!B74:D85,3,-1)} -> Summer Sale Campaign | B49: 953038.5 | C49: 7526106.3 | D49: =ROUND((C49-B49)/B49,1) -> 6.9
A50: Retargeting Campaign | B50: 737503.08 | C50: 5903948.4 | D50: =ROUND((C50-B50)/B50,1) -> 7
A51: New Product Launch | B51: 550311.75 | C51: 4710860.2 | D51: =ROUND((C51-B51)/B51,1) -> 7.6
A52: Email Promotion | B52: 377693.37 | C52: 3321507.8 | D52: =ROUND((C52-B52)/B52,1) -> 7.8
...

Sheet DASHBOARD

Sheet Insights

Sheet DATASET
B5: Date | C5: Region | D5: Product | E5: Category | F5: Campaign | G5: Marketing_Channel | H5: Quarter | I5: Spend | J5: Impressions | K5: Clicks | L5: Conversions | M5: Conversion Rate | N5: Revenue | O5: CTR | P5: CPC | Q5: ROI
B6: 45263 | C6: North | D6: Power Bank | E6: Electronics | F6: Social Media Boost Campaign | G6: Email | H6: Q1 | I6: 4341.92 | J6: 7948 | K6: 208 | L6: 49 | M6: 0.24 | N6: 5957.79 | O6: 0.0262 | P6: 20.87 | Q6: 0.3722
B7: 45270 | C7: West | D7: Gym Gloves | E7: Health & Fitness | F7: New Product Launch | G7: Social Media | H7: Q1 | I7: 3211.52 | J7: 7790 | K7: 886 | L7: 41 | M7: 0.05 | N7: 7313.16 | O7: 0.1137 | P7: 3.62 | Q7: 1.2772
B8: 45277 | C8: East | D8: Bluetooth Speaker | E8: Electronics | F8: Summer Sale Campaign | G8: Search Engine | H8: Q1 | I8: 2828.02 | J8: 5429 | K8: 502 | L8: 17 | M8: 0.03 | N8: 5384.96 | O8: 0.0925 | P8: 5.63 | Q8: 0.9041
B9: 45284 | C9: North | D9: Yoga Mat | E9: Health & Fitness | F9: Loyalty Program Campaign | G9: Direct Mail | H9: Q3 | I9: 1730.76 | J9: 8184 | K9: 821 | L9: 33 | M9: 0.04 | N9: 7941.68 | O9: 0.1003 | P9: 2.11 | Q9: 3.5886
B10: 45291 | C10: South | D10: Gaming Mouse | E10: Electronics | F10: Summer Sale Campaign | G10: Direct Mail | H10: Q2 | I10: 4735.94 | J10: 5473 | K10: 761 | L10: 45 | M10: 0.06 | N10: 2492.35 | O10: 0.139 | P10: 6.22 | Q10: -0.4737
B11: 45270 | C11: West | D11: Sports Jacket | E11: Fashion | F11: Search Engine Ads Campaign | G11: Direct Mail | H11: Q3 | I11: 1451.91 | J11: 3573 | K11: 592 | L11: 28 | M11: 0.05 | N11: 18330.96 | O11: 0.1657 | P11: 2.45 | Q11: 11.6254
B12: 45277 | C12: South | D12: Mechanical Keyboard | E12: Electronics | F12: New Product Launch | G12: Email | H12: Q3 | I12: 1339.96 | J12: 2205 | K12: 849 | L12: 16 | M12: 0.02 | N12: 8983.12 | O12: 0.385 | P12: 1.58 | Q12: 5.704
B13: 45312 | C13: South | D13: Mechanical Keyboard | E13: Electronics | F13: Influencer Marketing Campaign | G13: Direct Mail | H13: Q3 | I13: 2387.81 | J13: 4006 | K13: 928 | L13: 9 | M13: 0.01 | N13: 2618.35 | O13: 0.2317 | P13: 2.57 | Q13: 0.0965
B14: 45319 | C14: South | D14: Yoga Pants | E14: Fashion | F14: Retargeting Campaign | G14: Search Engine | H14: Q4 | I14: 2547.39 | J14: 2428 | K14: 514 | L14: 31 | M14: 0.06 | N14: 2195.26 | O14: 0.2117 | P14: 4.96 | Q14: -0.1382
B15: 45326 | C15: North | D15: Yoga Pants | E15: Fashion | F15: New Product Launch | G15: Email | H15: Q1 | I15: 3258.37 | J15: 6139 | K15: 843 | L15: 34 | M15: 0.04 | N15: 16217.39 | O15: 0.1373 | P15: 3.87 | Q15: 3.9771
B16: 45333 | C16: North | D16: Gaming Mouse | E16: Electronics | F16: Retargeting Campaign | G16: Direct Mail | H16: Q2 | I16: 3091.34 | J16: 4665 | K16: 150 | L16: 37 | M16: 0.25 | N16: 18223.16 | O16: 0.0322 | P16: 20.61 | Q16: 4.8949
B17: 45340 | C17: South | D17: Gym Gloves | E17: Health & Fitness | F17: Retargeting Campaign | G17: Social Media | H17: Q4 | I17: 1761.01 | J17: 5688 | K17: 315 | L17: 21 | M17: 0.07 | N17: 15528.62 | O17: 0.0554 | P17: 5.59 | Q17: 7.818
... B1039: 45657 | C1039: North | D1039: Fitness Tracker | E1039: Electronics | F1039: Seasonal Discount Campaign | G1039: Direct Mail | H1039: Q4 | I1039: 7800 | J1039: 81000 | K1039: 2430 | L1039: 122 | M1039: 0.05 | N1039: 30375 | O1039: 0.03 | P1039: 3.21 | Q1039: 2.89

Sheet Pivot
B2: PRIMARY KPIs
B3: Row Labels | C3: Sum of Revenue | D3: Sum of Spend | E3: Sum of Impressions | F3: Sum of Conversions | G3: Average of CPC | H3: Sum of ROI
B4: 2023 | C4: 13464510 | D4: 1644658 | E4: 39222523 | F4: 83541 | G4: 1.4520946 | H4: 3582.3692
B5: 2024 | C5: 20113458 | D5: 2469314.9 | E5: 57705567 | F5: 124319 | G5: 1.8232203 | H5: 4573.2657
B6: Grand Total | C6: 33577968 | D6: 4113972.8 | E6: 96928090 | F6: 207860 | G6: 1.6638588 | H6: 8155.6349
B9: Monthly Revenue Trends (Selector)
B10: Sum of Revenue | C10: Column Labels
B11: Row Labels | C11: 2023 | D11: 2024 | E11: Grand Total
B12: Jan | C12: 589125 | D12: 1201288.6 | E12: 1790413.6
B13: Feb | C13: 720000 | D13: 1270928 | E13: 1990928
B14: Mar | C14: 779250 | D14: 1234813.9 | E14: 2014063.9
B15: Apr | C15: 902383.31 | D15: 1270451.2 | E15: 2172834.5
B16: May | C16: 1070748.3 | D16: 1590982.5 | E16: 2661730.8
B17: Jun | C17: 965588.26 | D17: 1443615.8 | E17: 2409204.1
B18: Jul | C18: 1290750 | D18: 1714874.9 | E18: 3005625
B19: Aug | C19: 1308973.2 | D19: 1861950.7 | E19: 3170923.9
B20: Sep | C20: 1233473 | D20: 2287855.2 | E20: 3521328.2
B21: Oct | C21: 1343468 | D21: 2190555.2 | E21: 3534023.2
B22: Nov | C22: 1428955.4 | D22: 2094258.2 | E22: 3523213.6
B23: Dec | C23: 1831795.7 | D23: 1951883.8 | E23: 3783679.5
B24: Grand Total | C24: 13464510 | D24: 20113458 | E24: 33577968
B27: Monthly Revenue Trends (Actual)
B28: Sum of Revenue | C28: Column Labels
B29: Row Labels | C29: 2023 | D29: 2024 | E29: Grand Total
B30: Jan | C30: 589125 | D30: 1201288.6 | E30: 1790413.6
B31: Feb | C31: 720000 | D31: 1270928 | E31: 1990928
B32: Mar | C32: 779250 | D32: 1234813.9 | E32: 2014063.9
B33: Apr | C33: 902383.31 | D33: 1270451.2 | E33: 2172834.5
B34: May | C34: 1070748.3 | D34: 1590982.5 | E34: 2661730.8
B35: Jun | C35: 965588.26 | D35: 1443615.8 | E35: 2409204.1
B36: Jul | C36: 1290750 | D36: 1714874.9 | E36: 3005625
B37: Aug | C37: 1308973.2 | D37: 1861950.7 | E37: 3170923.9
B38: Sep | C38: 1233473 | D38: 2287855.2 | E38: 3521328.2
B39: Oct | C39: 1343468 | D39: 2190555.2 | E39: 3534023.2
B40: Nov | C40: 1428955.4 | D40: 2094258.2 | E40: 3523213.6
B41: Dec | C41: 1831795.7 | D41: 1951883.8 | E41: 3783679.5
B42: Grand Total | C42: 13464510 | D42: 20113458 | E42: 33577968
B45: Revenue & Conversions by Channel
B46: Row Labels | C46: Sum of Revenue | D46: Sum of Conversions
B47: Direct Mail | C47: 4917146.7 | D47: 19518
...
